Workbook
Name Slicer_Signed_Copy: #N/A
Name Slicer_Status: #N/A
Name Slicer_Work_Type: #N/A

Sheet Agreements
B1: Agreements
B2: Client | C2: Contact | D2: Line of Business | E2: Business | F2: Contract Type | G2: Work Type | H2: Date Signed | I2: Description | J2: Signed Copy | K2: DocuSign | L2: Effective Date | M2: Duration (Months) | N2: Expiration Date | O2: Days to Contract End | P2: General Liability Insurance | Q2: COI Requirement | R2: GL Aggregate Limits | S2: GL per Occurrence | T2: Workers Compensation | U2: Employers Liability | V2: Umbrella Aggregate | W2: Umbrella per Occurrence | X2: Cyber Aggregate | Y2: Cyber per Occurrence | Z2: Professional Liability (E&O) | AA2: Property in Transit | AB2: Employee Theft of Client Property | AC2: Products/Completed Operations | AD2: Personal & Advertising Injury | AE2: Bodily Injury/Property Damage | AF2: Fire Legal Liability Injury | AG2: Medical Payments | AH2: Auto Insurance Combined Single Limit (Hired) | AI2: Auto Insurance Combined Single Limit (Non-owned) | AJ2: Auto Insurance Combined Single Limit (Owned) | AK2: R.A.G. Status | AL2: Notes | AM2: Path | AN2: Yes | AO2: No
B3: ABC Fitness Solutions, LLC | C3: =IFERROR(VLOOKUP(B3,'QB Consolidated Contacts'!$A$1:$F$333,6),"-") -> Prakash Rikhilal | E3: VNA | F3: MSA | G3: Agreement | I3: Master Services Agreement | J3: Yes | L3: 44053 | M3: ON-GOING | N3: =IFERROR(EDATE(L3,M3),"") | O3: =IFERROR(N3-TODAY(),"") | P3: Yes | R3: $1M | S3: $1M | V3: - | X3: - | Y3: - | AJ3: $100K | AK3: =IF(AGREEMENTS[[#This Row],[Days to Contract End]]<=90,"R",IF(AND(AGREEMENTS[[#This Row],[Days to Contract End]]<180),"A","G")) -> G
B4: Accelario Software Inc. | C4: =IFERROR(VLOOKUP(B4,'QB Consolidated Contacts'!$A$1:$F$333,6),"-") -> Prakash Rikhilal | E4: VT | F4: VAR Agreement | G4: Partnership | H4: 45770 | I4: ACCELARIO - Partnership Distribution Agr w Viscosity - clean version - final.docx | J4: Yes | K4: Yes | N4: =IFERROR(EDATE(L4,M4),"") -> 0 | O4: =IFERROR(N4-TODAY(),"") -> -46093 | AK4: =IF(AGREEMENTS[[#This Row],[Days to Contract End]]<=90,"R",IF(AND(AGREEMENTS[[#This Row],[Days to Contract End]]<180),"A","G")) -> R
B5: ACGI Software | C5: =IFERROR(VLOOKUP(B5,'QB Consolidated Contacts'!$A$1:$F$333,6),"-") -> Kevin Hostintler | E5: VNA | F5: MSA | G5: Agreement | I5: Master Services Agreement | J5: No | L5: 43252 | M5: ON-GOING | N5: =IFERROR(EDATE(L5,M5),"") | O5: =IFERROR(N5-TODAY(),"") | P5: Yes | R5: $1M | S5: $1M | V5: - | X5: - | Y5: - | AJ5: $100K | AK5: =IF(AGREEMENTS[[#This Row],[Days to Contract End]]<=90,"R",IF(AND(AGREEMENTS[[#This Row],[Days to Contract End]]<180),"A","G")) -> G | AL5: Last billed in 2018
B6: AMDI | C6: =IFERROR(VLOOKUP(B6,'QB Consolidated Contacts'!$A$1:$F$333,6),"-") -> Christina Green | E6: VNA | F6: MSA | G6: Agreement | I6: AMDI-MSA-2024-4854-1967-0962-v6.1 EXECUTED VNA.pdf | J6: No | K6: No | N6: =IFERROR(EDATE(L6,M6),"") -> 0 | O6: =IFERROR(N6-TODAY(),"") -> -46093 | AK6: =IF(AGREEMENTS[[#This Row],[Days to Contract End]]<=90,"R",IF(AND(AGREEMENTS[[#This Row],[Days to Contract End]]<180),"A","G")) -> R
B7: American Heart Association, Inc. | C7: =IFERROR(VLOOKUP(B7,'QB Consolidated Contacts'!$A$1:$F$333,6),"-") -> Roger Santone | E7: VNA | F7: MSA | G7: Agreement | I7: Master Services Agreement | J7: Yes | L7: 42880 | M7: ON-GOING | N7: =IFERROR(EDATE(L7,M7),"") | O7: =IFERROR(N7-TODAY(),"") | P7: Yes | R7: $2M | S7: $1M | V7: $5M | X7: $6M | Y7: $1M | AJ7: $1M | AK7: =IF(AGREEMENTS[[#This Row],[Days to Contract End]]<=90,"R",IF(AND(AGREEMENTS[[#This Row],[Days to Contract End]]<180),"A","G")) -> G
B8: American Leather | C8: =IFERROR(VLOOKUP(B8,'QB Consolidated Contacts'!$A$1:$F$333,6),"-") -> Roger Santone | E8: VNA | F8: MSA | G8: Agreement | I8: VNA.MSA.AMERICAN_LEATHER.2023.docx | J8: Yes | K8: Yes | L8: 45139 | M8: ON-GOING | N8: =IFERROR(EDATE(L8,M8),"") | O8: =IFERROR(N8-TODAY(),"") | AK8: =IF(AGREEMENTS[[#This Row],[Days to Contract End]]<=90,"R",IF(AND(AGREEMENTS[[#This Row],[Days to Contract End]]<180),"A","G")) -> G
B9: American Unit | C9: =IFERROR(VLOOKUP(B9,'QB Consolidated Contacts'!$A$1:$F$333,6),"-") -> Roger Santone | E9: VNA | F9: NDA | G9: Agreement | I9: MNDA - DW 092124 American Unit (Fully executed).pdf | V9: =IFERROR(EDATE(T9,U9),"") -> 0 | W9: =IFERROR(V9-TODAY(),"") -> -46093 | X9: =IF(SOWS[[#This Row],[Days to Contract End]]<=90,"R",IF(AND(SOWS[[#This Row],[Days to Contract End]]<180),"A","G")) -> R | AK9: =IF(AGREEMENTS[[#This Row],[Days to Contract End]]<=90,"R",IF(AND(AGREEMENTS[[#This Row],[Days to Contract End]]<180),"A","G")) -> R
B10: Apex Capital Corp. | E10: VNA | F10: NDA | G10: Agreement | H10: 45660 | I10: VNA.MNDA.2023 - Apex Capital Corp - Accepted.docx | J10: Yes | K10: Yes | L10: 45656 | M10: 36 | N10: =IFERROR(EDATE(L10,M10),"") -> 46751 | O10: =IFERROR(N10-TODAY(),"") -> 658 | AK10: =IF(AGREEMENTS[[#This Row],[Days to Contract End]]<=90,"R",IF(AND(AGREEMENTS[[#This Row],[Days to Contract End]]<180),"A","G")) -> G
B11: Apex Capital Corp. | C11: =IFERROR(VLOOKUP(B11,'QB Consolidated Contacts'!$A$1:$F$333,6),"-") -> 0 | E11: VT | F11: MSA | G11: Agreement | H11: 46021 | I11: VNA.MSA.2023_-_Apex_Capital_Corp.docx | J11: Yes | K11: Yes | L11: 45656 | M11: ON-GOING | N11: =IFERROR(EDATE(L11,M11),"") | O11: =IFERROR(N11-TODAY(),"") | AK11: =IF(AGREEMENTS[[#This Row],[Days to Contract End]]<=90,"R",IF(AND(AGREEMENTS[[#This Row],[Days to Contract End]]<180),"A","G")) -> G
B12: Athenian Group, LLC | C12: =IFERROR(VLOOKUP(B12,'QB Consolidated Contacts'!$A$1:$F$333,6),"-") -> 0 | E12: VNA | F12: MSA | G12: Agreement | H12: 45034 | I12: VNA - MSA 2022 .VNA REVISED.20230329.docx | J12: Yes | L12: 45016 | M12: 36 | N12: =IFERROR(EDATE(L12,M12),"") -> 46112 | O12: =IFERROR(N12-TODAY(),"") -> 19 | AK12: =IF(AGREEMENTS[[#This Row],[Days to Contract End]]<=90,"R",IF(AND(AGREEMENTS[[#This Row],[Days to Contract End]]<180),"A","G")) -> R
B13: Athenian Group, LLC | C13: =IFERROR(VLOOKUP(B13,'QB Consolidated Contacts'!$A$1:$F$333,6),"-") -> 0 | E13: VNA | F13: NDA | G13: Agreement | H13: 44883 | I13: VNA -Athenian -MNDA November 2022.doc | J13: Yes | L13: 44883 | M13: 24 | N13: =IFERROR(EDATE(L13,M13),"") -> 45614 | O13: =IFERROR(N13-TODAY(),"") -> -479 | P13: No | AK13: =IF(AGREEMENTS[[#This Row],[Days to Contract End]]<=90,"R",IF(AND(AGREEMENTS[[#This Row],[Days to Contract End]]<180),"A","G")) -> R
B14: BMW | C14: =IFERROR(VLOOKUP(B14,'QB Consolidated Contacts'!$A$1:$F$333,6),"-") -> 0 | E14: VNA | F14: MSA | G14: Agreement | I14: Master Services Agreement | J14: No | N14: =IFERROR(EDATE(L14,M14),"") -> 0 | O14: =IFERROR(N14-TODAY(),"") -> -46093 | P14: Yes | R14: $5M | S14: $5M | T14: Statutory Limits | U14: $1M | AJ14: $1M | AK14: =IF(AGREEMENTS[[#This Row],[Days to Contract End]]<=90,"R",IF(AND(AGREEMENTS[[#This Row],[Days to Contract End]]<180),"A","G")) -> R | AL14: We assumed this client when we bought Sumner Technologies in 2018; I went through some of that stuff and can’t find anything.
B15: BMW | C15: =IFERROR(VLOOKUP(B15,'QB Consolidated Contacts'!$A$1:$F$333,6),"-") -> 0 | E15: VNA | F15: NDA | G15: Agreement | I15: Non-Disclosure Agreement | J15: No | N15: =IFERROR(EDATE(L15,M15),"") -> 0 | O15: =IFERROR(N15-TODAY(),"") -> -46093 | AK15: =IF(AGREEMENTS[[#This Row],[Days to Contract End]]<=90,"R",IF(AND(AGREEMENTS[[#This Row],[Days to Contract End]]<180),"A","G")) -> R
B16: CableOne | C16: =IFERROR(VLOOKUP(B16,'QB Consolidated Contacts'!$A$1:$F$333,6),"-") -> 0 | E16: VT | F16: MSA | G16: Agreement | I16: (SOW) Statement of Work with Cable One, Inc_ (667af9e7f9) (version 1) | J16: Yes | K16: No | L16: 45469 | N16: =IFERROR(EDATE(L16,M16),"") -> 45469 | O16: =IFERROR(N16-TODAY(),"") -> -624 | P16: - | Q16: Certificate Holder | R16: $2M | U16: $1M | Z16: $1M | AC16: S1M | AD16: S1M | AE16: $1M | AH16: $1M | AI16: $2M | AK16: =IF(AGREEMENTS[[#This Row],[Days to Contract End]]<=90,"R",IF(AND(AGREEMENTS[[#This Row],[Days to Contract End]]<180),"A","G")) -> R
B17: CACI | C17: =IFERROR(VLOOKUP(B17,'QB Consolidated Contacts'!$A$1:$F$333,6),"-") -> 0 | E17: VNA | F17: NDA | G17: Agreement | I17: CACI_Agreement.NDA.12022022 | J17: Yes | L17: 44897 | M17: 36 | N17: =IFERROR(EDATE(L17,M17),"") -> 45993 | O17: =IFERROR(N17-TODAY(),"") -> -100 | AK17: =IF(AGREEMENTS[[#This Row],[Days to Contract End]]<=90,"R",IF(AND(AGREEMENTS[[#This Row],[Days to Contract End]]<180),"A","G")) -> R
B18: CACI - LGS Labs | C18: =IFERROR(VLOOKUP(B18,'QB Consolidated Contacts'!$A$1:$F$333,6),"-") -> 0 | E18: VNA | F18: NDA | G18: Agreement | I18: Non-Disclosure Agreement | J18: Yes | L18: 44887 | M18: 36 | N18: =IFERROR(EDATE(L18,M18),"") -> 45983 | O18: =IFERROR(N18-TODAY(),"") -> -110 | P18: Yes | R18: $2M | S18: $1M | T18: $500K | AC18: $1M | AD18: $1M | AF18: $300K | AG18: $10K | AH18: $1M | AK18: =IF(AGREEMENTS[[#This Row],[Days to Contract End]]<=90,"R",IF(AND(AGREEMENTS[[#This Row],[Days to Contract End]]<180),"A","G")) -> R
B19: CACI - LGS Labs | C19: =IFERROR(VLOOKUP(B19,'QB Consolidated Contacts'!$A$1:$F$333,6),"-") -> 0 | F19: MSA | G19: Agreement | I19: Master Services Agreement | J19: No | L19: 26 | N19: =IFERROR(EDATE(L19,M19),"") -> 26 | O19: =IFERROR(N19-TODAY(),"") -> -46067 | AK19: =IF(AGREEMENTS[[#This Row],[Days to Contract End]]<=90,"R",IF(AND(AGREEMENTS[[#This Row],[Days to Contract End]]<180),"A","G")) -> R
B20: Captial Title of Texas | C20: =IFERROR(VLOOKUP(B20,'QB Consolidated Contacts'!$A$1:$F$333,6),"-") -> 0 | E20: VNA | F20: MSA | G20: Agreement | I20: Master Services Agreement | J20: Yes | L20: 44102 | M20: ON-GOING | N20: =IFERROR(EDATE(L20,M20),"") | O20: =IFERROR(N20-TODAY(),"") | P20: Yes | S20: S1M | AJ20: $100K | AK20: =IF(AGREEMENTS[[#This Row],[Days to Contract End]]<=90,"R",IF(AND(AGREEMENTS[[#This Row],[Days to Contract End]]<180),"A","G")) -> G
B21: Centene - [formerly Wellcare] - [formerly Meridian (Caidan)] | C21: =IFERROR(VLOOKUP(B21,'QB Consolidated Contacts'!$A$1:$F$333,6),"-") -> 0 | E21: VNA | F21: MSA | G21: Agreement | I21: PROC380 VISCOSITY NORTH AMERICA, MSA,AMD1_encrypted_.pdf | J21: Yes | K21: Yes | L21: 45491 | M21: 12 | N21: =IFERROR(EDATE(L21,M21),"")-10 -> 45846 | O21: =IFERROR(N21-TODAY(),"") -> -247 | AK21: =IF(AGREEMENTS[[#This Row],[Days to Contract End]]<=90,"R",IF(AND(AGREEMENTS[[#This Row],[Days to Contract End]]<180),"A","G")) -> R
B22: Civic Telehealth | C22: =IFERROR(VLOOKUP(B22,'QB Consolidated Contacts'!$A$1:$F$333,6),"-") -> 0 | E22: VNA | F22: NDA | G22: Agreement | I22: mNDA CTH Civic Telehealth.pdf | J22: Yes | K22: Yes | N22: =IFERROR(EDATE(L22,M22),"") -> 0 | O22: =IFERROR(N22-TODAY(),"") -> -46093 | AK22: =IF(AGREEMENTS[[#This Row],[Days to Contract End]]<=90,"R",IF(AND(AGREEMENTS[[#This Row],[Days to Contract End]]<180),"A","G")) -> R
B23: Clario | C23: =IFERROR(VLOOKUP(B23,'QB Consolidated Contacts'!$A$1:$F$333,6),"-") -> 0 | E23: VT | F23: MSA | G23: Agreement | I23: Master Services Agreement | J23: Yes | L23: 44869 | M23: 24 | N23: =IFERROR(EDATE(L23,M23),"") -> 45600 | O23: =IFERROR(N23-TODAY(),"") -> -493 | AK23: =IF(AGREEMENTS[[#This Row],[Days to Contract End]]<=90,"R",IF(AND(AGREEMENTS[[#This Row],[Days to Contract End]]<180),"A","G")) -> R | AL23: It appears that the redlines have not been resolved and there is no signed MSA currently in effect. Nonetheless, we do have an active PO.
B24: Clario | C24: =IFERROR(VLOOKUP(B24,'QB Consolidated Contacts'!$A$1:$F$333,6),"-") -> 0 | E24: VT | F24: NDA | G24: Agreement | I24: Non-Disclosure Agreement | J24: Yes | L24: 44778 | M24: =5*12 -> 60 | N24: =IFERROR(EDATE(L24,M24),"") -> 46604 | O24: =IFERROR(N24-TODAY(),"") -> 511 | AK24: =IF(AGREEMENTS[[#This Row],[Days to Contract End]]<=90,"R",IF(AND(AGREEMENTS[[#This Row],[Days to Contract End]]<180),"A","G")) -> G
B25: COE | C25: =IFERROR(VLOOKUP(B25,'QB Consolidated Contacts'!$A$1:$F$333,6),"-") -> 0 | E25: VNA | F25: MSA | G25: Agreement | I25: Master Services Agreement | J25: Yes | L25: 43089 | M25: ON-GOING | N25: =IFERROR(EDATE(L25,M25),"") | O25: =IFERROR(N25-TODAY(),"") | P25: Yes | R25: $1M | S25: $1M | V25: - | X25: - | Y25: - | AJ25: $100K | AK25: =IF(AGREEMENTS[[#This Row],[Days to Contract End]]<=90,"R",IF(AND(AGREEMENTS[[#This Row],[Days to Contract End]]<180),"A","G")) -> G
B26: College of American Pathologists (“CAP”) | C26: =IFERROR(VLOOKUP(B26,'QB Consolidated Contacts'!$A$1:$F$333,6),"-") -> 0 | F26: MSA | G26: Agreement | I26: PO 87781 Viscosity MASTER SERVICES AGREEMENT | N26: =IFERROR(EDATE(L26,M26),"") -> 0 | O26: =IFERROR(N26-TODAY(),"") -> -46093 | AK26: =IF(AGREEMENTS[[#This Row],[Days to Contract End]]<=90,"R",IF(AND(AGREEMENTS[[#This Row],[Days to Contract End]]<180),"A","G")) -> R
B27: Computex Technology Solutions | C27: =IFERROR(VLOOKUP(B27,'QB Consolidated Contacts'!$A$1:$F$333,6),"-") -> 0 | E27: VNA | F27: MSA | G27: Agreement | I27: Master Services Agreement | J27: Yes | L27: 44258 | M27: ON-GOING | N27: =IFERROR(EDATE(L27,M27),"") | O27: =IFERROR(N27-TODAY(),"") | P27: Yes | R27: $2M | S27: $1M | T27: $1M | V27: $5M | W27: $1M | Z27: $5M | AA27: $1M | AB27: $1M | AJ27: $1M | AK27: =IF(AGREEMENTS[[#This Row],[Days to Contract End]]<=90,"R",IF(AND(AGREEMENTS[[#This Row],[Days to Contract End]]<180),"A","G")) -> G
B28: Computex Technology Solutions | C28: =IFERROR(VLOOKUP(B28,'QB Consolidated Contacts'!$A$1:$F$333,6),"-") -> 0 | E28: VNA | F28: NDA | G28: Agreement | I28: Non-Disclosure Agreement | J28: Yes | L28: 44270 | M28: ON-GOING | N28: =IFERROR(EDATE(L28,M28),"") | O28: =IFERROR(N28-TODAY(),"") | P28: No | AK28: =IF(AGREEMENTS[[#This Row],[Days to Contract End]]<=90,"R",IF(AND(AGREEMENTS[[#This Row],[Days to Contract End]]<180),"A","G")) -> G | AL28: A Recipient’s duty to protect Confidential Information expires three (3) years from the date of any disclosure hereunder
B29: Cynet | C29: =IFERROR(VLOOKUP(B29,'QB Consolidated Contacts'!$A$1:$F$333,6),"-") -> 0 | N29: =IFERROR(EDATE(L29,M29),"") -> 0 | O29: =IFERROR(N29-TODAY(),"") -> -46093 | AK29: =IF(AGREEMENTS[[#This Row],[Days to Contract End]]<=90,"R",IF(AND(AGREEMENTS[[#This Row],[Days to Contract End]]<180),"A","G")) -> R
B30: Dominion Questar | C30: =IFERROR(VLOOKUP(B30,'QB Consolidated Contacts'!$A$1:$F$333,6),"-") -> 0 | E30: VNA | F30: Fifth Amendment Agreement | G30: Agreement | I30: New Agreement PO# 50104298; Old Agreement #6163-01A-57112 | J30: Yes | L30: 44779 | M30: ON-GOING | N30: =IFERROR(EDATE(L30,M30),"") | O30: =IFERROR(N30-TODAY(),"") | AK30: =IF(AGREEMENTS[[#This Row],[Days to Contract End]]<=90,"R",IF(AND(AGREEMENTS[[#This Row],[Days to Contract End]]<180),"A","G")) -> G
B31: Drill Tech Drilling & Shoring, Inc. | C31: =IFERROR(VLOOKUP(B31,'QB Consolidated Contacts'!$A$1:$F$333,6),"-") -> 0 | E31: VNA | F31: MSA | G31: Agreement | I31: VNA MSA (Drill Tech) - 07.18.2024.pdf | J31: Yes | K31: Yes | L31: 45491 | M31: ON-GOING | N31: =IFERROR(EDATE(L31,M31),"") | O31: =IFERROR(N31-TODAY(),"") | AK31: =IF(AGREEMENTS[[#This Row],[Days to Contract End]]<=90,"R",IF(AND(AGREEMENTS[[#This Row],[Days to Contract End]]<180),"A","G")) -> G
B32: Fleet Farm | C32: =IFERROR(VLOOKUP(B32,'QB Consolidated Contacts'!$A$1:$F$333,6),"-") -> 0 | E32: VT | F32: MSA | G32: Unknown | J32: No | N32: =IFERROR(EDATE(L32,M32),"") -> 0 | O32: =IFERROR(N32-TODAY(),"") -> -46093 | AK32: =IF(AGREEMENTS[[#This Row],[Days to Contract End]]<=90,"R",IF(AND(AGREEMENTS[[#This Row],[Days to Contract End]]<180),"A","G")) -> R
B33: Florida Realtors | C33: =IFERROR(VLOOKUP(B33,'QB Consolidated Contacts'!$A$1:$F$333,6),"-") -> 0 | E33: VT | F33: MSA | G33: Agreement | I33: Master Services Agreement | J33: Yes | L33: 44232 | M33: ON-GOING | N33: =IFERROR(EDATE(L33,M33),"") | O33: =IFERROR(N33-TODAY(),"") | P33: Yes | S33: $1M | AJ33: $100K | AK33: =IF(AGREEMENTS[[#This Row],[Days to Contract End]]<=90,"R",IF(AND(AGREEMENTS[[#This Row],[Days to Contract End]]<180),"A","G")) -> G
B34: Flowtrac | C34: =IFERROR(VLOOKUP(B34,'QB Consolidated Contacts'!$A$1:$F$333,6),"-") -> 0 | E34: VNA | F34: NDA | G34: Agreement | I34: Non-Disclosure Agreement | J34: Yes | K34: No | L34: 45061 | M34: 24 | N34: =IFERROR(EDATE(L34,M34),"") -> 45792 | O34: =IFERROR(N34-TODAY(),"") -> -301 | AK34: =IF(AGREEMENTS[[#This Row],[Days to Contract End]]<=90,"R",IF(AND(AGREEMENTS[[#This Row],[Days to Contract End]]<180),"A","G")) -> R
B35: FNF | C35: =IFERROR(VLOOKUP(B35,'QB Consolidated Contacts'!$A$1:$F$333,6),"-") -> 0 | E35: VNA | F35: MSA | G35: Agreement | I35: Master Services Agreement | J35: Yes | K35: Yes | L35: 43243 | M35: ON-GOING | N35: =IFERROR(EDATE(L35,M35),"") | O35: =IFERROR(N35-TODAY(),"") | AK35: =IF(AGREEMENTS[[#This Row],[Days to Contract End]]<=90,"R",IF(AND(AGREEMENTS[[#This Row],[Days to Contract End]]<180),"A","G")) -> G
B36: Follett Content Soultions LLC (SQL Server) | C36: =IFERROR(VLOOKUP(B36,'QB Consolidated Contacts'!$A$1:$F$333,6),"-") -> 0 | D36: Legal Agreement | E36: VT | F36: MBE_WBE Statement | G36: Agreement | I36: VT.MSA.Follett Content Solutions.27JAN2024 Follett Content Edits.FINAL.docx | J36: Yes | K36: Yes | L36: 45315 | M36: ON-GOING | N36: =IFERROR(EDATE(L36,M36),"") | O36: =IFERROR(N36-TODAY(),"") | S36: $1M | AJ36: $100k | AK36: =IF(AGREEMENTS[[#This Row],[Days to Contract End]]<=90,"R",IF(AND(AGREEMENTS[[#This Row],[Days to Contract End]]<180),"A","G")) -> G
B37: Follett Content Soultions LLC (SQL Server) | C37: =IFERROR(VLOOKUP(B37,'QB Consolidated Contacts'!$A$1:$F$333,6),"-") -> 0 | D37: Legal Agreement | E37: VT | F37: NDA | G37: Agreement | I37: VT.MNDA.Follett Content Solutions.24JAN2024 (002) Follett Comments FINAL.doc | J37: Yes | K37: Yes | L37: 45324 | M37: 24 | N37: =IFERROR(EDATE(L37,M37),"") -> 46055 | O37: =IFERROR(N37-TODAY(),"") -> -38 | AK37: =IF(AGREEMENTS[[#This Row],[Days to Contract End]]<=90,"R",IF(AND(AGREEMENTS[[#This Row],[Days to Contract End]]<180),"A","G")) -> R
B38: Follett School Solutions LLC (Oracle EBS) | C38: =IFERROR(VLOOKUP(B38,'QB Consolidated Contacts'!$A$1:$F$333,6),"-") -> 0 | D38: Legal Agreement | E38: VT | F38: MSA | G38: Agreement | I38: Master Services Agreement | J38: Yes | L38: 44732 | M38: ON-GOING | N38: =IFERROR(EDATE(L38,M38),"") | O38: =IFERROR(N38-TODAY(),"") | P38: Yes | S38: $1M | AJ38: $100K | AK38: =IF(AGREEMENTS[[#This Row],[Days to Contract End]]<=90,"R",IF(AND(AGREEMENTS[[#This Row],[Days to Contract End]]<180),"A","G")) -> G
B39: Follett School Solutions LLC (Oracle EBS) | C39: =IFERROR(VLOOKUP(B39,'QB Consolidated Contacts'!$A$1:$F$333,6),"-") -> 0 | D39: Legal Agreement | E39: VT | F39: NDA | G39: Agreement | I39: Non-Disclosure Agreement | J39: Yes | L39: 44749 | M39: 24 | N39: =IFERROR(EDATE(L39,M39),"") -> 45480 | O39: =IFERROR(N39-TODAY(),"") -> -613 | AK39: =IF(AGREEMENTS[[#This Row],[Days to Contract End]]<=90,"R",IF(AND(AGREEMENTS[[#This Row],[Days to Contract End]]<180),"A","G")) -> R
B40: Globalstar | C40: =IFERROR(VLOOKUP(B40,'QB Consolidated Contacts'!$A$1:$F$333,6),"-") -> 0 | E40: VNA | F40: MSA | G40: Agreement | I40: Master Services Agreement | J40: Yes | K40: Yes | L40: 45016 | M40: ON-GOING | N40: =IFERROR(EDATE(L40,M40),"") | O40: =IFERROR(N40-TODAY(),"") | AK40: =IF(AGREEMENTS[[#This Row],[Days to Contract End]]<=90,"R",IF(AND(AGREEMENTS[[#This Row],[Days to Contract End]]<180),"A","G")) -> G
...

Sheet Partnerships - Referrals and Re
A1: Partnership - Referrals and Resell
A2: Company Name | B2: Referral or Resell | C2: Initial Contact Date | D2: Last Engagement Date | E2: Agreement | F2: Notes
A3: Accelario | B3: Referral | E3: ACCELARIO - Partnership Distribution Agr - Redlines 11Sept2024.docx | F3: Redlined new contract with DW's responses - pending approval to be sent.
A4: Accelario | E4: ACCELARIO - Partnership Distribution Agr w Viscosity - clean version - final.docx
A5: Confluent | B5: Resell | C5: 06.09.2023 | D5: 06.09.2023 | E5: Pending Viscosity Response | F5: Accepted - pending Partner Agreement acceptance
A6: Cynet | B6: Referral | C6: 05.24.2023 | D6: 05.31.2023 | E6: Pending Viscosity Response | F6: Meeting scheduled for 06.13.2023
A7: Solix | B7: Referral | D7: 06.12.2023 | E7: Pending Viscosity Response | F7: CK made edits on the attached link
A8: Solix | B8: Referral | D8: 06.12.2023 | E8: NDA_DocuSign executed 06.03.2023
A9: Databricks
A10: Microsoft
A11: Oracle
A12: Silk | E12: Silk_Mutual NDA_VNA_final.docx
A13: KeyTech
A14: AVNET

Sheet Statements of Work
B1: Statements of Work
B2: Company | C2: Client | D2: Business Line | E2: Contract Type | F2: Work Type | G2: Date Signed | H2: Effective Date | I2: Contract Name/Document Link | J2: Project Contact | K2: Signed Copy | L2: DocuSign | M2: Status | N2: Requires PO | O2: PO # | P2: Cycle | Q2: Payment Terms | R2: Monthly Budget | S2: Total Budget | T2: Block Of Hours | U2: Duration (Months) | V2: Expiration Date | W2: Days to Contract End | X2: R.A.G. Status | Y2: Discription of Project | AA2: Yes | AB2: No
B3: VNA | C3: ABC Fitness Solutions, LLC | D3: Infrastructure | E3: SOW | F3: Professional Services | G3: 44979 | I3: ABC.India Offshore DBA SOW.20230217.docx | J3: =IFERROR(VLOOKUP(Agreements!B123,'QB Consolidated Contacts'!$A$1:$F$333,6),"-") -> - | V3: =IFERROR(EDATE(Agreements!U123,Agreements!V123),"") -> 0 | W3: =IFERROR(Agreements!W123-TODAY(),"") -> -46093 | X3: =IF(SOWS[[#This Row],[Days to Contract End]]<=90,"R",IF(AND(SOWS[[#This Row],[Days to Contract End]]<180),"A","G")) -> R
B4: VNA | C4: ABC Fitness Solutions, LLC | D4: Infrastructure | E4: SOW | F4: Professional Services | H4: 44586 | I4: ABC-Fitness BI - Azure DevOps Integration | J4: =IFERROR(VLOOKUP(C4,'QB Consolidated Contacts'!$A$1:$F$333,6),"-") -> Prakash Rikhilal | K4: Yes | M4: Unknown | N4: Yes | P4: Block of Hours | S4: 229600 | T4: 1312 | U4: ON-GOING | V4: =IFERROR(EDATE(H4,U4),"") | W4: =IFERROR(V4-TODAY(),"") | X4: =IF(SOWS[[#This Row],[Days to Contract End]]<=90,"R",IF(AND(SOWS[[#This Row],[Days to Contract End]]<180),"A","G")) -> G
B5: VNA | C5: ABC Fitness Solutions, LLC | D5: Infrastructure | E5: SOW | F5: Professional Services | H5: 44621 | I5: ABC - Professional Services | J5: =IFERROR(VLOOKUP(C5,'QB Consolidated Contacts'!$A$1:$F$333,6),"-") -> Prakash Rikhilal | K5: Yes | M5: Unknown | N5: Yes | O5: PO23-29200 | P5: Block of Hours | S5: 91000 | T5: 520 | U5: ON-GOING | V5: =IFERROR(EDATE(H5,U5),"") | W5: =IFERROR(V5-TODAY(),"") | X5: =IF(SOWS[[#This Row],[Days to Contract End]]<=90,"R",IF(AND(SOWS[[#This Row],[Days to Contract End]]<180),"A","G")) -> G
B6: VNA | C6: ABC Fitness Solutions, LLC | D6: Infrastructure | E6: SOW | F6: Professional Services | G6: 45069 | H6: 45063 | I6: VNA.ABC_DBA Professional Services_SoW_May 2023.docx | J6: =IFERROR(VLOOKUP(C6,'QB Consolidated Contacts'!$A$1:$F$333,6),"-") -> Prakash Rikhilal | K6: Yes | L6: Yes | M6: Unknown | T6: 60/week | U6: ON-GOING | V6: =IFERROR(EDATE(H6,U6),"") | W6: =IFERROR(V6-TODAY(),"") | X6: =IF(SOWS[[#This Row],[Days to Contract End]]<=90,"R",IF(AND(SOWS[[#This Row],[Days to Contract End]]<180),"A","G")) -> G
B7: VNA | C7: ABC Fitness Solutions, LLC | D7: Infrastructure | E7: SOW | F7: Professional Services | H7: 45214 | I7: VNA.ABC_Professional Services_SoW_Q4 2023.docx | J7: =IFERROR(VLOOKUP(C7,'QB Consolidated Contacts'!$A$1:$F$333,6),"-") -> Prakash Rikhilal | K7: Yes | L7: Yes | M7: Unknown | N7: Yes | T7: =332+24 -> 356 | U7: TBD | V7: =IFERROR(EDATE(H7,U7),"") | W7: =IFERROR(V7-TODAY(),"") | X7: =IF(SOWS[[#This Row],[Days to Contract End]]<=90,"R",IF(AND(SOWS[[#This Row],[Days to Contract End]]<180),"A","G")) -> G
B8: VT | C8: ABC Fitness Solutions, LLC | D8: Infrastructure | E8: SOW | F8: Managed Services | H8: 44739 | I8: Offshore - Monitoring & Support | J8: =IFERROR(VLOOKUP(C8,'QB Consolidated Contacts'!$A$1:$F$333,6),"-") -> Prakash Rikhilal | K8: Yes | M8: Unknown | N8: Yes | P8: Monthly | R8: 13410 | S8: =SOWS[[#This Row],[Monthly Budget]]*12 -> 160920 | T8: =106+106+10 -> 222 | U8: 12 | V8: =IFERROR(EDATE(H8,U8),"") -> 45104 | W8: =IFERROR(V8-TODAY(),"") -> -989 | X8: =IF(SOWS[[#This Row],[Days to Contract End]]<=90,"R",IF(AND(SOWS[[#This Row],[Days to Contract End]]<180),"A","G")) -> R
B9: VNA | C9: ABC Fitness Solutions, LLC | D9: Infrastructure | E9: SOW | F9: Managed Services | H9: 44972 | I9: Offshore - DBA Support | J9: =IFERROR(VLOOKUP(C9,'QB Consolidated Contacts'!$A$1:$F$333,6),"-") -> Prakash Rikhilal | K9: Yes | M9: Unknown | N9: Yes | P9: Block of Hours | R9: 9000 | S9: =SOWS[[#This Row],[Monthly Budget]]*12 -> 108000 | T9: 40 hrs/week | U9: 12 | V9: =IFERROR(EDATE(H9,U9),"") -> 45337 | W9: =IFERROR(V9-TODAY(),"") -> -756 | X9: =IF(SOWS[[#This Row],[Days to Contract End]]<=90,"R",IF(AND(SOWS[[#This Row],[Days to Contract End]]<180),"A","G")) -> R
B10: VNA | C10: ABC Fitness Solutions, LLC | D10: Infrastructure | E10: SOW | F10: Managed Services | H10: 45108 | I10: VNA.ABC.Managed Services SoW.EDW Monitoring.Offshore.2023July.docx | J10: =IFERROR(VLOOKUP(C10,'QB Consolidated Contacts'!$A$1:$F$333,6),"-") -> Prakash Rikhilal | K10: Yes | L10: Yes | M10: Unknown | N10: Yes | O10: PO22-24864 | U10: 6 | V10: =IFERROR(EDATE(H10,U10),"") -> 45292 | W10: =IFERROR(V10-TODAY(),"") -> -801 | X10: =IF(SOWS[[#This Row],[Days to Contract End]]<=90,"R",IF(AND(SOWS[[#This Row],[Days to Contract End]]<180),"A","G")) -> R
B11: VNA | C11: ABC Fitness Solutions, LLC | D11: Infrastructure | E11: SOW | F11: Assessment | I11: VNA.ABC.PF-Get Well-Insights Assessment.SoW.2024Sep.docx | J11: =IFERROR(VLOOKUP(Agreements!B133,'QB Consolidated Contacts'!$A$1:$F$333,6),"-") -> - | V11: =IFERROR(EDATE(Agreements!U133,Agreements!V133),"") -> 0 | W11: =IFERROR(Agreements!W133-TODAY(),"") -> -46093 | X11: =IF(SOWS[[#This Row],[Days to Contract End]]<=90,"R",IF(AND(SOWS[[#This Row],[Days to Contract End]]<180),"A","G")) -> R
B12: VNA | C12: ABC Fitness Solutions, LLC | D12: Infrastructure | E12: SOW | F12: Managed Services | H12: 45292 | I12: VNA.ABC.Professional Services.SoW.2024Jan-Jun.docx | J12: =IFERROR(VLOOKUP(C12,'QB Consolidated Contacts'!$A$1:$F$333,6),"-") -> Prakash Rikhilal | K12: Yes | L12: Yes | M12: Unknown | U12: TBD | V12: 45658 | W12: =IFERROR(V12-TODAY(),"") -> -435 | X12: =IF(SOWS[[#This Row],[Days to Contract End]]<=90,"R",IF(AND(SOWS[[#This Row],[Days to Contract End]]<180),"A","G")) -> R
B13: VNA | C13: ABC Fitness Solutions, LLC | D13: Infrastructure | E13: SOW | F13: Managed Services | I13: VNA.ABC.Support Services SoW.EDW Monitoring.Offshore.2024Jan-Jun.docx | J13: =IFERROR(VLOOKUP(Agreements!B134,'QB Consolidated Contacts'!$A$1:$F$333,6),"-") -> - | V13: =IFERROR(EDATE(Agreements!U134,Agreements!V134),"") -> 0 | W13: =IFERROR(Agreements!W134-TODAY(),"") -> -46093 | X13: =IF(SOWS[[#This Row],[Days to Contract End]]<=90,"R",IF(AND(SOWS[[#This Row],[Days to Contract End]]<180),"A","G")) -> R
B14: VNA | C14: ABC Fitness Solutions, LLC | D14: Infrastructure | E14: SOW | F14: Professional Services | I14: VNA.ABC.Professional Services.SoW.2024Jun-Dec | J14: =IFERROR(VLOOKUP(Agreements!B135,'QB Consolidated Contacts'!$A$1:$F$333,6),"-") -> - | V14: =IFERROR(EDATE(Agreements!U135,Agreements!V135),"") -> 0 | W14: =IFERROR(Agreements!W135-TODAY(),"") -> -46093 | X14: =IF(SOWS[[#This Row],[Days to Contract End]]<=90,"R",IF(AND(SOWS[[#This Row],[Days to Contract End]]<180),"A","G")) -> R
B15: VNA | C15: ABC Fitness Solutions, LLC | D15: Infrastructure | E15: SOW | F15: Professional Services | I15: VNA.ABC.Professional Services.SoW.2024Jan-Jun.docx | J15: =IFERROR(VLOOKUP(Agreements!B135,'QB Consolidated Contacts'!$A$1:$F$333,6),"-") -> - | V15: =IFERROR(EDATE(Agreements!U135,Agreements!V135),"") -> 0 | W15: =IFERROR(Agreements!W135-TODAY(),"") -> -46093 | X15: =IF(SOWS[[#This Row],[Days to Contract End]]<=90,"R",IF(AND(SOWS[[#This Row],[Days to Contract End]]<180),"A","G")) -> R
B16: VNA | C16: ABC Fitness Solutions, LLC | D16: Infrastructure | E16: SOW | F16: Managed Services | H16: 45751 | I16: VNA.ABC.Support Services SoW.EDW Monitoring.Offshore.2025Apr-Jun.docx | J16: =IFERROR(VLOOKUP(Agreements!B139,'QB Consolidated Contacts'!$A$1:$F$333,6),"-") -> - | K16: Yes | L16: Yes | V16: =IFERROR(EDATE(Agreements!U139,Agreements!V139),"") -> 0 | W16: =IFERROR(Agreements!W139-TODAY(),"") -> -46093 | X16: =IF(SOWS[[#This Row],[Days to Contract End]]<=90,"R",IF(AND(SOWS[[#This Row],[Days to Contract End]]<180),"A","G")) -> R
B17: VNA | C17: ABC Fitness Solutions, LLC | D17: Infrastructure | E17: SOW | F17: Managed Services | I17: VNA.ABC.Support Services SoW.EDW Monitoring.Offshore.2025Jan-Mar.v2.docx | J17: =IFERROR(VLOOKUP(Agreements!B138,'QB Consolidated Contacts'!$A$1:$F$333,6),"-") -> - | K17: Yes | L17: Yes | V17: =IFERROR(EDATE(Agreements!U138,Agreements!V138),"") -> 0 | W17: =IFERROR(Agreements!W138-TODAY(),"") -> -46093 | X17: =IF(SOWS[[#This Row],[Days to Contract End]]<=90,"R",IF(AND(SOWS[[#This Row],[Days to Contract End]]<180),"A","G")) -> R
B18: VNA | C18: ABC Fitness Solutions, LLC | D18: Infrastructure | E18: SOW | F18: Professional Services | I18: VNA.ABC.Support Services SoW.Offshore DBA.2024Mar-Dec.docx | J18: =IFERROR(VLOOKUP(Agreements!B136,'QB Consolidated Contacts'!$A$1:$F$333,6),"-") -> - | V18: =IFERROR(EDATE(Agreements!U136,Agreements!V136),"") -> 0 | W18: =IFERROR(Agreements!W136-TODAY(),"") -> -46093 | X18: =IF(SOWS[[#This Row],[Days to Contract End]]<=90,"R",IF(AND(SOWS[[#This Row],[Days to Contract End]]<180),"A","G")) -> R
B19: VNA | C19: ABC Fitness Solutions, LLC | D19: Infrastructure | E19: SOW | F19: Managed Services | H19: 45292 | I19: VNA.ABC.Support Services SoW.EDW Monitoring.Offshore.2024Jan-Jun.docx | J19: =IFERROR(VLOOKUP(C19,'QB Consolidated Contacts'!$A$1:$F$333,6),"-") -> Prakash Rikhilal | K19: Yes | L19: Yes | M19: Unknown | U19: TBD | V19: 45657 | W19: =IFERROR(V19-TODAY(),"") -> -436 | X19: =IF(SOWS[[#This Row],[Days to Contract End]]<=90,"R",IF(AND(SOWS[[#This Row],[Days to Contract End]]<180),"A","G")) -> R
B20: VNA | C20: ABC Fitness Solutions, LLC | D20: Infrastructure | E20: SOW | F20: Managed Services | H20: 45352 | I20: VNA.ABC.Support Services SoW.Offshore DBA.2024Mar-Dec.docx | J20: =IFERROR(VLOOKUP(C20,'QB Consolidated Contacts'!$A$1:$F$333,6),"-") -> Prakash Rikhilal | K20: Yes | L20: Yes | M20: Unknown | U20: 10 | V20: 45657 | W20: =IFERROR(V20-TODAY(),"") -> -436 | X20: =IF(SOWS[[#This Row],[Days to Contract End]]<=90,"R",IF(AND(SOWS[[#This Row],[Days to Contract End]]<180),"A","G")) -> R
B21: VNA | C21: ABC Fitness Solutions, LLC | D21: Infrastructure | E21: SOW | F21: Managed Services | H21: 45474 | I21: VNA.ABC.Support Services SoW.EDW Monitoring.Offshore.2024Jul-Dec.docx.pdf | J21: =IFERROR(VLOOKUP(C21,'QB Consolidated Contacts'!$A$1:$F$333,6),"-") -> Prakash Rikhilal | K21: Yes | L21: Yes | M21: Unknown | N21: Need PO | U21: 6 | V21: =IFERROR(EDATE(H21,U21),"") -> 45658 | W21: =IFERROR(V21-TODAY(),"") -> -435 | X21: =IF(SOWS[[#This Row],[Days to Contract End]]<=90,"R",IF(AND(SOWS[[#This Row],[Days to Contract End]]<180),"A","G")) -> R
B22: VNA | C22: ABC Fitness Solutions, LLC | D22: Infrastructure | E22: SOW | I22: ExaCC DB Migration-Optimization-Support | J22: =IFERROR(VLOOKUP(C22,'QB Consolidated Contacts'!$A$1:$F$333,6),"-") -> Prakash Rikhilal | K22: Yes | L22: Yes | V22: =IFERROR(EDATE(Agreements!U122,Agreements!V122),"") -> 0 | W22: =IFERROR(Agreements!W122-TODAY(),"") -> -46093 | X22: =IF(SOWS[[#This Row],[Days to Contract End]]<=90,"R",IF(AND(SOWS[[#This Row],[Days to Contract End]]<180),"A","G")) -> R
B23: VNA | C23: ABC Fitness Solutions, LLC | D23: Infrastructure | E23: SOW | F23: Professional Services | G23: 45845 | I23: VNA.ABC.Azure Data Monitoring & Dashboard.SoW.May 2025 | J23: =IFERROR(VLOOKUP(Agreements!B122,'QB Consolidated Contacts'!$A$1:$F$333,6),"-") -> - | K23: Yes | L23: Yes | V23: =IFERROR(EDATE(Agreements!U122,Agreements!V122),"") -> 0 | W23: =IFERROR(Agreements!W122-TODAY(),"") -> -46093 | X23: =IF(SOWS[[#This Row],[Days to Contract End]]<=90,"R",IF(AND(SOWS[[#This Row],[Days to Contract End]]<180),"A","G")) -> R
B24: VNA | C24: ABC Fitness Solutions, LLC | D24: Infrastructure | E24: SOW | F24: Professional Services | G24: 45838 | I24: VNA.ABC.Professional Services.SoW.2025Jul-Dec | J24: =IFERROR(VLOOKUP(Agreements!B313,'QB Consolidated Contacts'!$A$1:$F$333,6),"-") -> - | V24: =IFERROR(EDATE(Agreements!U313,Agreements!V313),"") -> 0 | W24: =IFERROR(Agreements!W313-TODAY(),"") -> -46093 | X24: =IF(SOWS[[#This Row],[Days to Contract End]]<=90,"R",IF(AND(SOWS[[#This Row],[Days to Contract End]]<180),"A","G")) -> R
B25: VNA | C25: ACGI Software | D25: Infrastructure | E25: SOW | F25: Managed Services | H25: 44713 | I25: On Demand Consulting - Signed | J25: =IFERROR(VLOOKUP(C25,'QB Consolidated Contacts'!$A$1:$F$333,6),"-") -> Kevin Hostintler | K25: Yes | M25: Inactive | P25: - | T25: 135/hour | U25: ON-GOING | V25: =IFERROR(EDATE(H25,U25),"") | W25: =IFERROR(V25-TODAY(),"") | X25: =IF(SOWS[[#This Row],[Days to Contract End]]<=90,"R",IF(AND(SOWS[[#This Row],[Days to Contract End]]<180),"A","G")) -> G
B26: VNA | C26: Airport Terminal Services | D26: Infrastructure | E26: SOW | F26: Managed Services | H26: 43466 | I26: Oracle ERP Managed Services | J26: =IFERROR(VLOOKUP(C26,'QB Consolidated Contacts'!$A$1:$F$333,6),"-") -> Christina Green | K26: Yes | M26: Inactive | P26: Monthly | R26: 4500 | T26: 30 | U26: ON-GOING | V26: =IFERROR(EDATE(H26,U26),"") | W26: =IFERROR(V26-TODAY(),"") | X26: =IF(SOWS[[#This Row],[Days to Contract End]]<=90,"R",IF(AND(SOWS[[#This Row],[Days to Contract End]]<180),"A","G")) -> G
B27: VNA | C27: AMDI | D27: Development | E27: SOW | F27: Professional Services | H27: 45412 | I27: VNA SOW AMDI OEPortal Fully executed.pdf | J27: Gabriela Codina | K27: Yes | L27: Yes | M27: Active | U27: 16 | V27: =IFERROR(EDATE(H27,U27)+1,"") -> 45900 | W27: =IFERROR(V27-TODAY(),"") -> -193 | X27: =IF(SOWS[[#This Row],[Days to Contract End]]<=90,"R",IF(AND(SOWS[[#This Row],[Days to Contract End]]<180),"A","G")) -> R
C28: AMDI | J28: =IFERROR(VLOOKUP(Agreements!B138,'QB Consolidated Contacts'!$A$1:$F$333,6),"-") -> - | V28: =IFERROR(EDATE(Agreements!U138,Agreements!V138),"") -> 0 | W28: =IFERROR(Agreements!W138-TODAY(),"") -> -46093 | X28: =IF(SOWS[[#This Row],[Days to Contract End]]<=90,"R",IF(AND(SOWS[[#This Row],[Days to Contract End]]<180),"A","G")) -> R
C29: AMDI | J29: =IFERROR(VLOOKUP(Agreements!B138,'QB Consolidated Contacts'!$A$1:$F$333,6),"-") -> - | V29: =IFERROR(EDATE(Agreements!U138,Agreements!V138),"") -> 0 | W29: =IFERROR(Agreements!W138-TODAY(),"") -> -46093 | X29: =IF(SOWS[[#This Row],[Days to Contract End]]<=90,"R",IF(AND(SOWS[[#This Row],[Days to Contract End]]<180),"A","G")) -> R
B30: VNA | C30: American Heart Association, Inc. | D30: Infrastructure | E30: SOW | F30: Managed Services | H30: 44743 | I30: DBA Managed Services | J30: =IFERROR(VLOOKUP(C30,'QB Consolidated Contacts'!$A$1:$F$333,6),"-") -> Roger Santone | K30: Yes | M30: Expired | P30: Monthly | R30: 5000 | S30: =SOWS[[#This Row],[Monthly Budget]]*12 -> 60000 | T30: 30 | U30: 11 | V30: =IFERROR(EOMONTH(H30,U30),"") -> 45107 | W30: =IFERROR(V30-TODAY(),"") -> -986 | X30: =IF(SOWS[[#This Row],[Days to Contract End]]<=90,"R",IF(AND(SOWS[[#This Row],[Days to Contract End]]<180),"A","G")) -> R
B31: VNA | C31: AMERICAN LEATHER HOLDINGS, LLC | D31: Development | E31: SOW | F31: Managed Services | I31: SOW-VNA.AL_-EBS_WebServices.Remote_Support_Services.20240823.EXECUTED | J31: =IFERROR(VLOOKUP(Agreements!B144,'QB Consolidated Contacts'!$A$1:$F$333,6),"-") -> - | K31: Yes | L31: Yes | V31: =IFERROR(EDATE(Agreements!U144,Agreements!V144),"") -> 0 | W31: =IFERROR(Agreements!W144-TODAY(),"") -> -46093 | X31: =IF(SOWS[[#This Row],[Days to Contract End]]<=90,"R",IF(AND(SOWS[[#This Row],[Days to Contract End]]<180),"A","G")) -> R
B32: VNA | C32: AMERICAN LEATHER HOLDINGS, LLC | D32: Development | E32: Change Order | F32: Professional Services | I32: ALO_B2B_Portal-_Enhancements__BRD_V2.0.EXECUTED | J32: =IFERROR(VLOOKUP(Agreements!B144,'QB Consolidated Contacts'!$A$1:$F$333,6),"-") -> - | K32: Yes | L32: Yes | V32: =IFERROR(EDATE(Agreements!U144,Agreements!V144),"") -> 0 | W32: =IFERROR(Agreements!W144-TODAY(),"") -> -46093 | X32: =IF(SOWS[[#This Row],[Days to Contract End]]<=90,"R",IF(AND(SOWS[[#This Row],[Days to Contract End]]<180),"A","G")) -> R
B33: VNA | C33: AMERICAN LEATHER HOLDINGS, LLC | D33: Development | E33: SOW | F33: Managed Services | I33: SOW.AMERICAN LEATHER.VNA SWATCH MANAGED SERVICES.APR2024.docx | J33: =IFERROR(VLOOKUP(Agreements!B144,'QB Consolidated Contacts'!$A$1:$F$333,6),"-") -> - | K33: Yes | L33: Yes | V33: =IFERROR(EDATE(Agreements!U144,Agreements!V144),"") -> 0 | W33: =IFERROR(Agreements!W144-TODAY(),"") -> -46093 | X33: =IF(SOWS[[#This Row],[Days to Contract End]]<=90,"R",IF(AND(SOWS[[#This Row],[Days to Contract End]]<180),"A","G")) -> R
B34: VNA | C34: AMERICAN LEATHER HOLDINGS, LLC | D34: Development | E34: Change Order | F34: Professional Services | H34: 45636 | I34: CO.AL.LEE.00001.DB2WebservicesDec2024.docx | J34: =IFERROR(VLOOKUP(Agreements!B141,'QB Consolidated Contacts'!$A$1:$F$333,6),"-") -> - | K34: Yes | L34: Yes | M34: Unknown | T34: 80 | U34: 12 | V34: =IFERROR(EDATE(Agreements!U141,Agreements!V141),"") -> 0 | W34: =IFERROR(Agreements!W141-TODAY(),"") -> -46093 | X34: =IF(SOWS[[#This Row],[Days to Contract End]]<=90,"R",IF(AND(SOWS[[#This Row],[Days to Contract End]]<180),"A","G")) -> R
B35: VNA | C35: AMERICAN LEATHER HOLDINGS, LLC | D35: Development | E35: Change Order | F35: Professional Services | H35: 45506 | I35: CO.AL.EBSWS.00002.Swatch-User Portal Integration.V2 | J35: =IFERROR(VLOOKUP(Agreements!B141,'QB Consolidated Contacts'!$A$1:$F$333,6),"-") -> - | M35: Unknown | V35: =IFERROR(EDATE(Agreements!U141,Agreements!V141),"") -> 0 | W35: =IFERROR(Agreements!W141-TODAY(),"") -> -46093 | X35: =IF(SOWS[[#This Row],[Days to Contract End]]<=90,"R",IF(AND(SOWS[[#This Row],[Days to Contract End]]<180),"A","G")) -> R
B36: VNA | C36: AMERICAN LEATHER HOLDINGS, LLC | D36: Development | E36: SOW | F36: Professional Services | H36: 45118 | I36: APEX Staff Augmentation- Transfer Views from Oracle to Alternative Data Store | J36: =IFERROR(VLOOKUP(C36,'QB Consolidated Contacts'!$A$1:$F$333,6),"-") -> Roger Santone | K36: Yes | L36: Yes | M36: Active | T36: 80 | U36: TBD | V36: =IFERROR(EDATE(H36,U36),"") | W36: =IFERROR(V36-TODAY(),"") | X36: =IF(SOWS[[#This Row],[Days to Contract End]]<=90,"R",IF(AND(SOWS[[#This Row],[Days to Contract End]]<180),"A","G")) -> G
B37: VT | C37: AMERICAN LEATHER HOLDINGS, LLC | D37: Development | E37: SOW | F37: Managed Services | G37: 45699 | I37: SOW-VT.AL -Lee WebServices.Remote Support Services.2025.docx | J37: =IFERROR(VLOOKUP(Agreements!B141,'QB Consolidated Contacts'!$A$1:$F$333,6),"-") -> - | K37: Yes | L37: Yes | M37: Unknown | U37: 12 | V37: =IFERROR(EDATE(Agreements!U141,Agreements!V141),"") -> 0 | W37: =IFERROR(Agreements!W141-TODAY(),"") -> -46093 | X37: =IF(SOWS[[#This Row],[Days to Contract End]]<=90,"R",IF(AND(SOWS[[#This Row],[Days to Contract End]]<180),"A","G")) -> R
B38: VNA | C38: AMERICAN LEATHER HOLDINGS, LLC | D38: Development | E38: SOW | F38: Professional Services | H38: 45160 | I38: SOW.American_Leather.Web_Services.SOW.ORACLE_EBS.AUG2023.docx | J38: =IFERROR(VLOOKUP(C38,'QB Consolidated Contacts'!$A$1:$F$333,6),"-") -> Roger Santone | K38: Yes | L38: Yes | M38: Active | U38: TBD | V38: =IFERROR(EDATE(H38,U38),"") | W38: =IFERROR(V38-TODAY(),"") | X38: =IF(SOWS[[#This Row],[Days to Contract End]]<=90,"R",IF(AND(SOWS[[#This Row],[Days to Contract End]]<180),"A","G")) -> G
B39: VT | C39: AMERICAN LEATHER HOLDINGS, LLC | D39: Development | E39: SOW | F39: Professional Services | H39: ** | I39: SOW-VT.AL -EBS WebServices.Remote Support Services.20240823.REISSUE.docx | J39: =IFERROR(VLOOKUP(Agreements!B141,'QB Consolidated Contacts'!$A$1:$F$333,6),"-") -> - | K39: Yes | L39: Yes | M39: Unknown | U39: 36 | V39: =IFERROR(EDATE(Agreements!U141,Agreements!V141),"") -> 0 | W39: =IFERROR(Agreements!W141-TODAY(),"") -> -46093 | X39: =IF(SOWS[[#This Row],[Days to Contract End]]<=90,"R",IF(AND(SOWS[[#This Row],[Days to Contract End]]<180),"A","G")) -> R
B40: VNA | C40: AMERICAN LEATHER HOLDINGS, LLC | D40: Development | E40: Change Order | F40: Professional Services | H40: 45523 | I40: ALO_B2B_Portal-_Enhancements__BRD_V2.0.EXECUTED.pdf | J40: =IFERROR(VLOOKUP(C40,'QB Consolidated Contacts'!$A$1:$F$333,6),"-") -> Roger Santone | K40: Yes | L40: Yes | M40: Active | P40: Block of Hours | S40: 21000 | T40: 120 | U40: TBD | V40: =IFERROR(EDATE(H40,U40),"") | W40: =IFERROR(V40-TODAY(),"") | X40: =IF(SOWS[[#This Row],[Days to Contract End]]<=90,"R",IF(AND(SOWS[[#This Row],[Days to Contract End]]<180),"A","G")) -> G
...

Sheet MS Dev Renewals
A1: Work Type | B1: (Multiple Items)
A2: R.A.G. Status | B2: (Multiple Items)
A3: Status | B3: (Multiple Items)
A5: Row Labels
A6: ABC Fitness Solutions, LLC
A7: American Heart Association, Inc. | B7: DEAD
A8: Captial Title of Texas
A9: COE
A10: Dallas Independent School District
A11: IdenTrust
A12: Identrust Db Patching 2022
A13: 45175
A14: IdenTrust DB Patching 2023
A15: 45506
A16: IdenTrust Retainer Services - Schedule A VT - Signed
A17: 44418
A18: STGenetics
A19: AMERICAN LEATHER HOLDINGS, LLC
A20: Dominion Energy Services, Inc.

Sheet Settings & Instructions
A1: Contract Type | B1: Description | C1: Work Type | D1: Line of Business | E1: Status | F1: Term and Renewal | I1: vnacontratsadministration@viscosityna.com
A2: Addendum | B2: Consultant Service Agreement | C2: Agreement | D2: Development | E2: Active | F2: Evergreen
A3: Change Order | B3: Master Service Agreement OR Managed Service Agreement | C3: Amendment | D3: Infrastructure | E3: Expired | F3: Fixed-Term
A4: CSA | B4: Non-Disclosure Agreement | C4: AOP Renewal | D4: Unknown | E4: Inactive | F4: Mutal Agreement
A5: Fifth Amendment Agreement | B5: Statement of Work | C5: Assessment | D5: Project Management | E5: Pending | F5: Evergreen w/ Price Adjust.
A6: HIPAA | C6: Managed Services | D6: Legal Agreement | E6: Unknown | F6: Conditional Renewal
A7: Limited Services Agreement | C7: Professional Services | E7: Redlines
A8: MBE_WBE Statement | B8: SMB Certificate | C8: Purchase Order
A9: MCSA | B9: Master Contractor Services Agreement | C9: Partnership
A10: MSA | C10: Retainer Services
A11: NDA | C11: Staff Aug
A12: PO | C12: Unknown
A13: Renewal | C13: Change Order
A14: Retainer Services | C14: Addendum
A15: SOW | C15: Order Document
A16: Sales & Use Tax Addendum
A17: VAR Agreement
A18: Referral Agreement
A19: Resell Agreement

Sheet Software | Licensing Agreements
B1: Software | Licensing Agreements
B2: Business | C2: Client | D2: Product | E2: Contract Name | F2: Signed Copy | G2: Status | H2: Requires PO | I2: Notes
C3: AMDI | D3: AMP | E3: n/a | G3: Pending | I3: New Customers, will be in production this year 2024.
C4: American Leather | D4: AMP | E4: n/a | G4: Active | I4: The project paused, but they’re in production; not sure as of when.
C5: NGCSI | D5: AMP | E5: n/a | G5: Active | I5: Recent /New customer, they went to production recently sometime around June 2024.
C6: SMRTL | D6: AMP | E6: n/a | G6: Pending | I6: Recent/New customers, will be in production soon June 2024
C7: STgenetics | D7: AMP | E7: n/a | G7: Unknown | I7: I am not sure if we ever billed them for AMP or if they are aware they have to pay for AMP subscription and do not know next steps to rectify as years have passed
C8: COE | D8: AMP | E8: n/a- not seeing it list in SOWs either | G8: Unknown | I8: I am not sure if we ever billed them for AMP or if they are aware they have to pay for AMP subscription and do not know next steps to rectify as years have passed.
C9: Region 10 | D9: AMP | E9: Pending David Wangs Approval | G9: Pending | I9: Recent/New customer, will be in production soon June 2024.
B10: VNA | C10: Capital Title of Texas | D10: AMP | E10: Viscosity_AMP_EULA -CTOT.pdf | F10: No Signed Copy | G10: Unknown | I10: I am not sure if we ever billed them for AMP or if they are aware they have to pay for AMP subscription and do not know next steps to rectify as years have passed.
B11: VNA | C11: National Mango Board | D11: AMP | E11: Viscosity_AMP_EULA -NMB Internal.04302021.pdf | F11: No Signed Copy | G11: Active | I11: They have been in production for a while, and we know for sure they are paying their subscription.
B12: VNA | C12: Sherwin Williams | D12: AMP | E12: Viscosity_AMP_Software_License_Agreement_08112020.docx | F12: Yes - DocuSign | G12: Active | I12: They have been in production for a while, and we know for sure they are paying their subscription.

Sheet Contracts
B2: Client | C2: Contact | D2: Line of Business | E2: Contract Type | F2: Work Type | G2: Project Manager | H2: Description | I2: Signed Copy | J2: DocuSign | K2: Status | L2: Business | M2: Requires PO | N2: PO # | O2: Cycle | P2: Payment Terms | Q2: Monthly Budget | R2: Total Budget | S2: Block Of Hours | T2: Effective Date | U2: Duration (Months) | V2: Expiration Date | W2: Days to Contract End | X2: General Liability Insurance | Y2: COI Requirement | Z2: GL Aggregate Limits | AA2: GL per Occurrence | AB2: Workers Compensation | AC2: Employers Liability | AD2: Umbrella Aggregate | AE2: Umbrella per Occurrence | AF2: Cyber Aggregate | AG2: Cyber per Occurrence | AH2: Professional Liability (E&O) | AI2: Property in Transit | AJ2: Employee Theft of Client Property | AK2: Products/Completed Operations | AL2: Personal & Advertising Injury | AM2: Fire Legal Liability Injury | AN2: Medical Payments | AO2: Auto Insurance Combined Single Limit | AP2: Auto Insurance per Occurrence2 | AQ2: R.A.G. Status | AR2: Notes | AT2: Yes | AU2: No
B3: ABC Fitness Solutions, LLC | C3: =IFERROR(VLOOKUP(B3,'QB Consolidated Contacts'!$A$1:$F$333,6),"-") -> Prakash Rikhilal | E3: MSA | F3: Agreement | H3: Master Services Agreement | I3: Yes | K3: Active | L3: VNA | O3: - | S3: - | T3: 44053 | U3: ON-GOING | V3: =IFERROR(EDATE(T3,U3),"") | W3: =IFERROR(V3-TODAY(),"") | X3: Yes | Z3: $1M | AA3: $1M | AD3: - | AF3: - | AG3: - | AP3: $100K | AQ3: =IF(ALL_02FEB2024[[#This Row],[Days to Contract End]]<=90,"R",IF(AND(ALL_02FEB2024[[#This Row],[Days to Contract End]]<180),"A","G")) -> G
B4: ABC Fitness Solutions, LLC | C4: =IFERROR(VLOOKUP(B4,'QB Consolidated Contacts'!$A$1:$F$333,6),"-") -> Prakash Rikhilal | D4: Infrastructure | E4: SOW | F4: Managed Services | G4: Melissa Schuetter | H4: VNA.ABC.Managed Services SoW.EDW Monitoring.Offshore.2023July.docx | I4: Yes | J4: Yes | K4: Active | L4: VNA | N4: PO22-24864 | T4: 45108 | U4: 6 | V4: =IFERROR(EDATE(T4,U4),"") -> 45292 | W4: =IFERROR(V4-TODAY(),"") -> -801 | AQ4: =IF(ALL_02FEB2024[[#This Row],[Days to Contract End]]<=90,"R",IF(AND(ALL_02FEB2024[[#This Row],[Days to Contract End]]<180),"A","G")) -> R
B5: ABC Fitness Solutions, LLC | C5: =IFERROR(VLOOKUP(B5,'QB Consolidated Contacts'!$A$1:$F$333,6),"-") -> Prakash Rikhilal | D5: Development | E5: SOW | F5: Managed Services | H5: Offshore - Monitoring & Support | I5: Yes | K5: Expired | L5: VT | M5: Yes | O5: Monthly | Q5: 13410 | R5: =ALL_02FEB2024[[#This Row],[Monthly Budget]]*12 -> 160920 | S5: =106+106+10 -> 222 | T5: 44739 | U5: 12 | V5: =IFERROR(EDATE(T5,U5),"") -> 45104 | W5: =IFERROR(V5-TODAY(),"") -> -989 | X5: No | AA5: - | AD5: - | AF5: - | AG5: - | AP5: - | AQ5: =IF(ALL_02FEB2024[[#This Row],[Days to Contract End]]<=90,"R",IF(AND(ALL_02FEB2024[[#This Row],[Days to Contract End]]<180),"A","G")) -> R
B6: ABC Fitness Solutions, LLC | C6: =IFERROR(VLOOKUP(B6,'QB Consolidated Contacts'!$A$1:$F$333,6),"-") -> Prakash Rikhilal | D6: Infrastructure | E6: SOW | F6: Managed Services | G6: Melissa Schuetter | H6: Offshore - DBA Support | I6: Yes | K6: Active | L6: VNA | M6: Yes | O6: Block of Hours | Q6: 9000 | R6: =ALL_02FEB2024[[#This Row],[Monthly Budget]]*12 -> 108000 | S6: 40 hrs/week | T6: 44972 | U6: 12 | V6: =IFERROR(EDATE(T6,U6),"") -> 45337 | W6: =IFERROR(V6-TODAY(),"") -> -756 | X6: No | Z6: - | AA6: - | AD6: - | AF6: - | AG6: - | AP6: - | AQ6: =IF(ALL_02FEB2024[[#This Row],[Days to Contract End]]<=90,"R",IF(AND(ALL_02FEB2024[[#This Row],[Days to Contract End]]<180),"A","G")) -> R
B7: ABC Fitness Solutions, LLC | C7: =IFERROR(VLOOKUP(B7,'QB Consolidated Contacts'!$A$1:$F$333,6),"-") -> Prakash Rikhilal | E7: SOW | F7: Managed Services | G7: Melissa Schuetter | H7: VNA.ABC.Professional Services.SoW.2024Jan-Jun.docx | I7: Yes | J7: Yes | K7: Active | L7: VNA | T7: 45292 | U7: TBD | V7: 45658 | W7: =IFERROR(V7-TODAY(),"") -> -435 | AQ7: =IF(ALL_02FEB2024[[#This Row],[Days to Contract End]]<=90,"R",IF(AND(ALL_02FEB2024[[#This Row],[Days to Contract End]]<180),"A","G")) -> R
B8: ABC Fitness Solutions, LLC | C8: =IFERROR(VLOOKUP(B8,'QB Consolidated Contacts'!$A$1:$F$333,6),"-") -> Prakash Rikhilal | E8: SOW | F8: Managed Services | G8: Melissa Schuetter | H8: VNA.ABC.Support Services SoW.EDW Monitoring.Offshore.2024Jan-Jun.docx | I8: Yes | J8: Yes | K8: Active | L8: VNA | T8: 45292 | U8: 6 | V8: =IFERROR(EDATE(T8,U8),"") -> 45474 | W8: =IFERROR(V8-TODAY(),"") -> -619 | AQ8: =IF(ALL_02FEB2024[[#This Row],[Days to Contract End]]<=90,"R",IF(AND(ALL_02FEB2024[[#This Row],[Days to Contract End]]<180),"A","G")) -> R
B9: ABC Fitness Solutions, LLC | C9: =IFERROR(VLOOKUP(B9,'QB Consolidated Contacts'!$A$1:$F$333,6),"-") -> Prakash Rikhilal | E9: SOW | F9: Managed Services | G9: Melissa Schuetter | H9: VNA.ABC.Support Services SoW.Offshore DBA.2024Mar-Dec.docx | I9: Yes | J9: Yes | K9: Active | L9: VNA | T9: 45352 | U9: 10 | V9: 45657 | W9: =IFERROR(V9-TODAY(),"") -> -436 | AQ9: =IF(ALL_02FEB2024[[#This Row],[Days to Contract End]]<=90,"R",IF(AND(ALL_02FEB2024[[#This Row],[Days to Contract End]]<180),"A","G")) -> R
B10: ABC Fitness Solutions, LLC | C10: =IFERROR(VLOOKUP(B10,'QB Consolidated Contacts'!$A$1:$F$333,6),"-") -> Prakash Rikhilal | D10: Infrastructure | E10: SOW | F10: Professional Services | G10: Melissa Schuetter | H10: ABC - Professional Services | I10: Yes | K10: Active | L10: VNA | M10: Yes | N10: PO23-29200 | O10: Block of Hours | R10: 91000 | S10: 520 | T10: 44621 | U10: ON-GOING | V10: =IFERROR(EDATE(T10,U10),"") | W10: =IFERROR(V10-TODAY(),"") | X10: No | Z10: - | AA10: - | AD10: - | AF10: - | AG10: - | AP10: - | AQ10: =IF(ALL_02FEB2024[[#This Row],[Days to Contract End]]<=90,"R",IF(AND(ALL_02FEB2024[[#This Row],[Days to Contract End]]<180),"A","G")) -> G
B11: ABC Fitness Solutions, LLC | C11: =IFERROR(VLOOKUP(B11,'QB Consolidated Contacts'!$A$1:$F$333,6),"-") -> Prakash Rikhilal | E11: SOW | F11: Professional Services | G11: Melissa Schuetter | H11: VNA.ABC_DBA Professional Services_SoW_May 2023.docx | I11: Yes | J11: Yes | K11: Active | L11: VNA | S11: 60/week | T11: 45069 | U11: ON-GOING | V11: =IFERROR(EDATE(T11,U11),"") | W11: =IFERROR(V11-TODAY(),"") | AQ11: =IF(ALL_02FEB2024[[#This Row],[Days to Contract End]]<=90,"R",IF(AND(ALL_02FEB2024[[#This Row],[Days to Contract End]]<180),"A","G")) -> G
B12: ABC Fitness Solutions, LLC | C12: =IFERROR(VLOOKUP(B12,'QB Consolidated Contacts'!$A$1:$F$333,6),"-") -> Prakash Rikhilal | E12: SOW | F12: Professional Services | G12: Melissa Schuetter | H12: VNA.ABC_Professional Services_SoW_Q4 2023.docx | I12: Yes | J12: Yes | K12: Active | L12: VNA | M12: Yes | S12: =332+24 -> 356 | T12: 45214 | U12: TBD | V12: =IFERROR(EDATE(T12,U12),"") | W12: =IFERROR(V12-TODAY(),"") | AQ12: =IF(ALL_02FEB2024[[#This Row],[Days to Contract End]]<=90,"R",IF(AND(ALL_02FEB2024[[#This Row],[Days to Contract End]]<180),"A","G")) -> G
B13: ABC Fitness Solutions, LLC | C13: =IFERROR(VLOOKUP(B13,'QB Consolidated Contacts'!$A$1:$F$333,6),"-") -> Prakash Rikhilal | D13: Infrastructure | E13: SOW | F13: Professional Services | G13: Melissa Schuetter | H13: ABC-Fitness BI - Azure DevOps Integration | I13: Yes | K13: Active | L13: VNA | M13: Yes | O13: Block of Hours | R13: 229600 | S13: 1312 | T13: 44586 | U13: ON-GOING | V13: =IFERROR(EDATE(T13,U13),"") | W13: =IFERROR(V13-TODAY(),"") | X13: No | Z13: - | AA13: - | AD13: - | AF13: - | AG13: - | AP13: - | AQ13: =IF(ALL_02FEB2024[[#This Row],[Days to Contract End]]<=90,"R",IF(AND(ALL_02FEB2024[[#This Row],[Days to Contract End]]<180),"A","G")) -> G
B14: ACGI Software | C14: =IFERROR(VLOOKUP(B14,'QB Consolidated Contacts'!$A$1:$F$333,6),"-") -> Kevin Hostintler | E14: MSA | F14: Agreement | H14: Master Services Agreement | I14: No | K14: Inactive | L14: VNA | O14: - | S14: - | T14: 43252 | U14: ON-GOING | V14: =IFERROR(EDATE(T14,U14),"") | W14: =IFERROR(V14-TODAY(),"") | X14: Yes | Z14: $1M | AA14: $1M | AD14: - | AF14: - | AG14: - | AP14: $100K | AQ14: =IF(ALL_02FEB2024[[#This Row],[Days to Contract End]]<=90,"R",IF(AND(ALL_02FEB2024[[#This Row],[Days to Contract End]]<180),"A","G")) -> G | AR14: Last billed in 2018
B15: ACGI Software | C15: =IFERROR(VLOOKUP(B15,'QB Consolidated Contacts'!$A$1:$F$333,6),"-") -> Kevin Hostintler | D15: Infrastructure | E15: SOW | F15: Managed Services | H15: On Demand Consulting - Signed | I15: Yes | K15: Inactive | L15: VNA | O15: - | S15: 135/hour | T15: 44713 | U15: ON-GOING | V15: =IFERROR(EDATE(T15,U15),"") | W15: =IFERROR(V15-TODAY(),"") | X15: No | Z15: - | AA15: - | AD15: - | AF15: - | AG15: - | AP15: - | AQ15: =IF(ALL_02FEB2024[[#This Row],[Days to Contract End]]<=90,"R",IF(AND(ALL_02FEB2024[[#This Row],[Days to Contract End]]<180),"A","G")) -> G
B16: Airport Terminal Services | C16: =IFERROR(VLOOKUP(B16,'QB Consolidated Contacts'!$A$1:$F$333,6),"-") -> Christina Green | D16: Infrastructure | E16: SOW | F16: Managed Services | H16: Oracle ERP Managed Services | I16: Yes | K16: Inactive | L16: VNA | O16: Monthly | Q16: 4500 | S16: 30 | T16: 43466 | U16: ON-GOING | V16: =IFERROR(EDATE(T16,U16),"") | W16: =IFERROR(V16-TODAY(),"") | X16: No | Z16: - | AA16: - | AD16: - | AF16: - | AG16: - | AP16: - | AQ16: =IF(ALL_02FEB2024[[#This Row],[Days to Contract End]]<=90,"R",IF(AND(ALL_02FEB2024[[#This Row],[Days to Contract End]]<180),"A","G")) -> G
B17: American Heart Association, Inc. | C17: =IFERROR(VLOOKUP(B17,'QB Consolidated Contacts'!$A$1:$F$333,6),"-") -> Roger Santone | D17: Infrastructure | E17: SOW | F17: Managed Services | H17: DBA Managed Services | I17: Yes | K17: Inactive | L17: VNA | O17: Monthly | Q17: 5000 | R17: =ALL_02FEB2024[[#This Row],[Monthly Budget]]*12 -> 60000 | S17: 30 | T17: 44743 | U17: Expired | V17: =IFERROR(EOMONTH(T17,U17),"") | W17: =IFERROR(V17-TODAY(),"") | X17: No | Z17: - | AA17: - | AD17: - | AF17: - | AG17: - | AP17: - | AQ17: =IF(ALL_02FEB2024[[#This Row],[Days to Contract End]]<=90,"R",IF(AND(ALL_02FEB2024[[#This Row],[Days to Contract End]]<180),"A","G")) -> G
B18: American Leather | C18: =IFERROR(VLOOKUP(B18,'QB Consolidated Contacts'!$A$1:$F$333,6),"-") -> Roger Santone | E18: MSA | F18: Agreement | H18: VNA.MSA.AMERICAN_LEATHER.2023.docx | I18: Yes | J18: Yes | K18: Active | L18: VNA | T18: 45139 | U18: ON-GOING | V18: =IFERROR(EDATE(T18,U18),"") | W18: =IFERROR(V18-TODAY(),"") | AQ18: =IF(ALL_02FEB2024[[#This Row],[Days to Contract End]]<=90,"R",IF(AND(ALL_02FEB2024[[#This Row],[Days to Contract End]]<180),"A","G")) -> G
B19: American Leather | C19: =IFERROR(VLOOKUP(B19,'QB Consolidated Contacts'!$A$1:$F$333,6),"-") -> Roger Santone | D19: Development | E19: SOW | F19: Professional Services | G19: Sabika Rizvi | H19: SOW.American_Leather.Web_Services.SOW.ORACLE_EBS.AUG2023.docx | I19: Yes | J19: Yes | K19: Active | L19: VNA | T19: 45160 | U19: TBD | V19: =IFERROR(EDATE(T19,U19),"") | W19: =IFERROR(V19-TODAY(),"") | AQ19: =IF(ALL_02FEB2024[[#This Row],[Days to Contract End]]<=90,"R",IF(AND(ALL_02FEB2024[[#This Row],[Days to Contract End]]<180),"A","G")) -> G
B20: American Leather | C20: =IFERROR(VLOOKUP(B20,'QB Consolidated Contacts'!$A$1:$F$333,6),"-") -> Roger Santone | D20: Development | E20: SOW | F20: Professional Services | G20: Beatriz Aguirre | H20: SOW_HRMS_and_Financial_Archiving..Executed | I20: Yes | J20: Yes | K20: Active | L20: VNA | M20: Yes | T20: 45152 | U20: TBD | V20: 45535 | W20: =IFERROR(V20-TODAY(),"") -> -558 | AQ20: =IF(ALL_02FEB2024[[#This Row],[Days to Contract End]]<=90,"R",IF(AND(ALL_02FEB2024[[#This Row],[Days to Contract End]]<180),"A","G")) -> R
B21: American Leather | C21: =IFERROR(VLOOKUP(B21,'QB Consolidated Contacts'!$A$1:$F$333,6),"-") -> Roger Santone | D21: Development | E21: SOW | F21: Professional Services | G21: Leisa Pitner | H21: APEX Staff Augmentation- Transfer Views from Oracle to Alternative Data Store | I21: Yes | J21: Yes | K21: Active | L21: VNA | S21: 80 | T21: 45118 | U21: TBD | V21: =IFERROR(EDATE(T21,U21),"") | W21: =IFERROR(V21-TODAY(),"") | AQ21: =IF(ALL_02FEB2024[[#This Row],[Days to Contract End]]<=90,"R",IF(AND(ALL_02FEB2024[[#This Row],[Days to Contract End]]<180),"A","G")) -> G
B22: American Leather | C22: =IFERROR(VLOOKUP(B22,'QB Consolidated Contacts'!$A$1:$F$333,6),"-") -> Roger Santone | D22: Development | E22: SOW | F22: Professional Services | G22: Leisa Pitner | H22: SOW.AMERICAN LEATHER.VNA STAFF AUGUMENTATION.APR2023.docx | I22: Yes | J22: Yes | K22: Active | L22: VNA | O22: Monthly | P22: - | Q22: 12250 | R22: =ALL_02FEB2024[[#This Row],[Monthly Budget]]*12 -> 147000 | S22: =16*12 -> 192 | T22: 45033 | U22: 12 | V22: =IFERROR(EDATE(T22,U22),"") -> 45399 | W22: =IFERROR(V22-TODAY(),"") -> -694 | AQ22: =IF(ALL_02FEB2024[[#This Row],[Days to Contract End]]<=90,"R",IF(AND(ALL_02FEB2024[[#This Row],[Days to Contract End]]<180),"A","G")) -> R
B23: American Heart Association, Inc. | C23: =IFERROR(VLOOKUP(B23,'QB Consolidated Contacts'!$A$1:$F$333,6),"-") -> Roger Santone | E23: MSA | F23: Agreement | H23: Master Services Agreement | I23: Yes | K23: Active | L23: VNA | O23: - | S23: - | T23: 42880 | U23: ON-GOING | V23: =IFERROR(EDATE(T23,U23),"") | W23: =IFERROR(V23-TODAY(),"") | X23: Yes | Z23: $2M | AA23: $1M | AD23: $5M | AF23: $6M | AG23: $1M | AP23: $1M | AQ23: =IF(ALL_02FEB2024[[#This Row],[Days to Contract End]]<=90,"R",IF(AND(ALL_02FEB2024[[#This Row],[Days to Contract End]]<180),"A","G")) -> G
B24: AssetWorks | C24: =IFERROR(VLOOKUP(B24,'QB Consolidated Contacts'!$A$1:$F$333,6),"-") -> 0 | D24: Infrastructure | E24: SOW | F24: Professional Services | H24: Asset Works Database and AOP Assessment SOW | I24: No | K24: Pending | L24: VNA | T24: 45036 | V24: =IFERROR(EDATE(T24,U24),"") -> 45036 | W24: 2693 | AQ24: =IF(ALL_02FEB2024[[#This Row],[Days to Contract End]]<=90,"R",IF(AND(ALL_02FEB2024[[#This Row],[Days to Contract End]]<180),"A","G")) -> G
B25: Athenian Group, LLC | C25: =IFERROR(VLOOKUP(B25,'QB Consolidated Contacts'!$A$1:$F$333,6),"-") -> 0 | E25: NDA | F25: Agreement | H25: Non-Disclosure Agreement | I25: Yes | K25: Active | L25: VNA | T25: 44883 | U25: 24 | V25: =IFERROR(EDATE(T25,U25),"") -> 45614 | W25: =IFERROR(V25-TODAY(),"") -> -479 | X25: No | AQ25: =IF(ALL_02FEB2024[[#This Row],[Days to Contract End]]<=90,"R",IF(AND(ALL_02FEB2024[[#This Row],[Days to Contract End]]<180),"A","G")) -> R
B26: Athenian Group, LLC - LA Metro | C26: =IFERROR(VLOOKUP(B26,'QB Consolidated Contacts'!$A$1:$F$333,6),"-") -> 0 | E26: MSA | F26: Agreement | H26: Master Services Agreement | I26: Yes | K26: Active | L26: VNA | T26: 45016 | U26: 36 | V26: =IFERROR(EDATE(T26,U26),"") -> 46112 | W26: =IFERROR(V26-TODAY(),"") -> 19 | AQ26: =IF(ALL_02FEB2024[[#This Row],[Days to Contract End]]<=90,"R",IF(AND(ALL_02FEB2024[[#This Row],[Days to Contract End]]<180),"A","G")) -> R
B27: Athenian Group, LLC - LA Metro | C27: =IFERROR(VLOOKUP(B27,'QB Consolidated Contacts'!$A$1:$F$333,6),"-") -> 0 | D27: Development | E27: SOW | F27: Professional Services | H27: Data Input/Automation POV | I27: Yes | K27: Expired | L27: VNA | T27: 45012 | U27: 2 | V27: =IFERROR(EDATE(T27,U27),"") -> 45073 | W27: =IFERROR(V27-TODAY(),"") -> -1020 | AQ27: =IF(ALL_02FEB2024[[#This Row],[Days to Contract End]]<=90,"R",IF(AND(ALL_02FEB2024[[#This Row],[Days to Contract End]]<180),"A","G")) -> R
